function checkMail() {
  return new Promise((resolve, reject) => {
    if (Math.random() > 0.5) {
      resolve('Mail has arrived');
    } else {
      reject(new Error('Failed to arrive'));
    }
  });
}

checkMail()
  .then((mail) => {
    console.log(mail);
  })
  .catch((err) => {
    throw new Error('Error from within catch block');
  })
  .finally(() => {
    console.log('Experiment completed');
  });
